<?xml version="1.0" encoding="utf-8"?>
<!-- =================================================================================== -->
<!-- |    This document was autogenerated by xacro from 1_hello.urdf.xacro             | -->
<!-- |    EDITING THIS FILE BY HAND IS NOT RECOMMENDED                                 | -->
<!-- =================================================================================== -->
<robot name="mycar">
  <link name="left_wheel">
    <visual>
      <geometry>
        <cylinder length="0.0015" radius="0.0325"/>
      </geometry>
      <origin rpy="1.57079635 0 0" xyz="0 0 0"/>
      <material name="wheel_color">
        <color rgba="0 0 0 0.3"/>
      </material>
    </visual>
  </link>
  <!-- 3-2.joint -->
  <joint name="left2link" type="continuous">
    <parent link="base_link"/>
    <child link="left_wheel"/>
    <origin rpy="0 0 0" xyz="0 0.1 -0.0225"/>
    <axis xyz="0 1 0"/>
  </joint>
  <link name="right_wheel">
    <visual>
      <geometry>
        <cylinder length="0.0015" radius="0.0325"/>
      </geometry>
      <origin rpy="1.57079635 0 0" xyz="0 0 0"/>
      <material name="wheel_color">
        <color rgba="0 0 0 0.3"/>
      </material>
    </visual>
  </link>
  <!-- 3-2.joint -->
  <joint name="right2link" type="continuous">
    <parent link="base_link"/>
    <child link="right_wheel"/>
    <origin rpy="0 0 0" xyz="0 -0.1 -0.0225"/>
    <axis xyz="0 1 0"/>
  </joint>
</robot>

